#VRML_SIM R2019a utf8
WorldInfo {
  basicTimeStep 4
  contactProperties [
    ContactProperties {
      coulombFriction [
        -1
      ]
      softCFM 0.0001
    }
  ]
}
Viewpoint {
  orientation 0.06791739884403188 -0.9942178253667879 -0.08317537290085325 4.243240988516501
  position 3.3890228506860463 1.3045084306980321 -1.5558713985021322
}
TexturedBackground {
}
TexturedBackgroundLight {
}
Floor {
  tileSize 1 1
}
Robot {
  translation 0 1.097 0
  children [
    SliderJoint {
      jointParameters JointParameters {
        axis 0 1 0
      }
      endPoint Solid {
        children [
          GPS {
            name "GPS"
          }
          DEF body Group {
            children [
              Transform {
                children [
                  Shape {
                    appearance Appearance {
                      material Material {
                        diffuseColor 0 0.3333333333333333 1
                      }
                    }
                    geometry Box {
                      size 0.4 0.3 0.2
                    }
                  }
                ]
              }
              Transform {
                translation 0 -0.225 0
                children [
                  Shape {
                    appearance Appearance {
                      material Material {
                        diffuseColor 0 0.3333333333333333 1
                      }
                    }
                    geometry Box {
                      size 0.2 0.15 0.2
                    }
                  }
                ]
              }
            ]
          }
          DEF r_roll HingeJoint {
            jointParameters HingeJointParameters {
              position 0.1708
              axis 0 0 -1
              anchor 0.1 -0.3 0
            }
            device [
              PositionSensor {
                name "X_r_roll"
              }
              RotationalMotor {
                name "R_roll_m"
                maxTorque 1000
              }
            ]
            endPoint Solid {
              translation 0.1 -0.3 0
              rotation 0 0 1 1.3999996938995745
              children [
                DEF r_roll_link Group {
                  children [
                    Transform {
                      rotation 1 0 0 1.5708003061004252
                      children [
                        Shape {
                          appearance Appearance {
                            material Material {
                            }
                          }
                          geometry Cylinder {
                            height 0.05
                            radius 0.019999999999999997
                            subdivision 10
                          }
                        }
                      ]
                    }
                    Transform {
                      translation 0 -0.05 0
                      rotation 0 0 1 0
                      children [
                        Shape {
                          appearance Appearance {
                            material Material {
                            }
                          }
                          geometry Cylinder {
                            height 0.1
                            radius 0.009999999999999998
                            subdivision 10
                          }
                        }
                      ]
                    }
                  ]
                }
                DEF r_pitch HingeJoint {
                  jointParameters HingeJointParameters {
                    position 0.6545
                    axis 0 1 0
                    anchor 0 -0.1 0
                  }
                  device [
                    PositionSensor {
                      name "X_r_thigh"
                    }
                    RotationalMotor {
                      name "R_thigh_m"
                      maxTorque 1000
                    }
                  ]
                  endPoint Solid {
                    translation 0 -0.1 0
                    rotation 0 1 0 0.6545
                    children [
                      DEF r_pitch_thigh Group {
                        children [
                          Transform {
                            children [
                              Shape {
                                appearance Appearance {
                                  material Material {
                                  }
                                }
                                geometry Cylinder {
                                  height 0.05
                                  radius 0.019999999999999997
                                  subdivision 10
                                }
                              }
                            ]
                          }
                          Transform {
                            translation -0.25 0 0
                            rotation 0 0 1 -1.5707996938995747
                            children [
                              Shape {
                                appearance Appearance {
                                  material Material {
                                  }
                                }
                                geometry Cylinder {
                                  height 0.5
                                  radius 0.020000000000000004
                                  subdivision 10
                                }
                              }
                            ]
                          }
                        ]
                      }
                      DEF r_knee HingeJoint {
                        jointParameters HingeJointParameters {
                          position -1.328
                          axis 0 1 0
                          anchor -0.5 0 0
                        }
                        device [
                          PositionSensor {
                            name "X_r_knee"
                          }
                          RotationalMotor {
                            name "R_knee_m"
                            maxTorque 5000
                          }
                        ]
                        endPoint Solid {
                          translation -0.5 0 0
                          rotation 0 -0.9999999999999999 0 1.3279999999999998
                          children [
                            DEF r_knee_shin Group {
                              children [
                                Transform {
                                  children [
                                    Shape {
                                      appearance Appearance {
                                        material Material {
                                        }
                                      }
                                      geometry Cylinder {
                                        height 0.05
                                        radius 0.019999999999999997
                                        subdivision 10
                                      }
                                    }
                                  ]
                                }
                                Transform {
                                  translation -0.24 0 0
                                  rotation 0 0 1 -1.5707996938995747
                                  children [
                                    Shape {
                                      appearance Appearance {
                                        material Material {
                                        }
                                      }
                                      geometry Cylinder {
                                        height 0.48
                                        radius 0.020000000000000004
                                        subdivision 10
                                      }
                                    }
                                  ]
                                }
                              ]
                            }
                            DEF r_foot TouchSensor {
                              translation -0.48 0 0
                              rotation 0 0 1 -1.5708003061004252
                              children [
                                DEF r_foot Shape {
                                  appearance Appearance {
                                    material Material {
                                    }
                                  }
                                  geometry Sphere {
                                    radius 0.020000000000000004
                                    subdivision 3
                                  }
                                }
                              ]
                              name "R_foot"
                              boundingObject USE r_foot
                              physics Physics {
                                density -1
                                mass 0.1
                                centerOfMass [
                                  0 0 0
                                ]
                              }
                              type "force-3d"
                              lookupTable [
                                -1000 -1000 0
                                5000 5000 0
                              ]
                            }
                          ]
                          boundingObject USE r_knee_shin
                          physics Physics {
                            density -1
                            mass 1
                            centerOfMass [
                              -0.24 0 0
                            ]
                          }
                        }
                      }
                    ]
                    boundingObject USE r_pitch_thigh
                    physics Physics {
                      density -1
                      mass 19.15
                      centerOfMass [
                        0 0 0
                      ]
                    }
                  }
                }
              ]
              boundingObject USE r_roll_link
              physics Physics {
                density -1
                mass 0.5
                centerOfMass [
                  0 0 0
                ]
              }
            }
          }
          DEF l_roll HingeJoint {
            jointParameters HingeJointParameters {
              position -0.1708
              axis 0 0 -1
              anchor -0.1 -0.3 0
            }
            device [
              RotationalMotor {
                name "L_roll_m"
                maxTorque 1000
              }
              PositionSensor {
                name "X_l_roll"
              }
            ]
            endPoint Solid {
              translation -0.1 -0.3 0
              rotation 0 0 -1 1.3999996938995745
              children [
                DEF r_roll_link Group {
                  children [
                    Transform {
                      rotation 1 0 0 1.5708003061004252
                      children [
                        Shape {
                          appearance Appearance {
                            material Material {
                            }
                          }
                          geometry Cylinder {
                            height 0.05
                            radius 0.019999999999999997
                            subdivision 10
                          }
                        }
                      ]
                    }
                    Transform {
                      translation 0 -0.05 0
                      rotation 0 0 1 0
                      children [
                        Shape {
                          appearance Appearance {
                            material Material {
                            }
                          }
                          geometry Cylinder {
                            height 0.1
                            radius 0.009999999999999998
                            subdivision 10
                          }
                        }
                      ]
                    }
                  ]
                }
                DEF l_pitch HingeJoint {
                  jointParameters HingeJointParameters {
                    position 0.6545
                    axis 0 -1 0
                    anchor 0 -0.1 0
                  }
                  device [
                    RotationalMotor {
                      name "L_thigh_m"
                      maxTorque 1000
                    }
                    PositionSensor {
                      name "X_l_thigh"
                    }
                  ]
                  endPoint Solid {
                    translation 0 -0.1 0
                    rotation 0 -1 0 0.6545
                    children [
                      DEF l_pitch_thigh Group {
                        children [
                          Transform {
                            children [
                              Shape {
                                appearance Appearance {
                                  material Material {
                                  }
                                }
                                geometry Cylinder {
                                  height 0.05
                                  radius 0.019999999999999997
                                  subdivision 10
                                }
                              }
                            ]
                          }
                          Transform {
                            translation 0.25 0 0
                            rotation 0 0 1 1.5707996938995747
                            children [
                              Shape {
                                appearance Appearance {
                                  material Material {
                                  }
                                }
                                geometry Cylinder {
                                  height 0.5
                                  radius 0.019999999999999997
                                  subdivision 10
                                }
                              }
                            ]
                          }
                        ]
                      }
                      DEF l_knee HingeJoint {
                        jointParameters HingeJointParameters {
                          position -1.328
                          axis 0 -1 0
                          anchor 0.5 0 0
                        }
                        device [
                          RotationalMotor {
                            name "L_knee_m"
                            maxTorque 5000
                          }
                          PositionSensor {
                            name "X_l_knee"
                          }
                        ]
                        endPoint Solid {
                          translation 0.5 0 0
                          rotation 0 0.9999999999999999 0 1.3279999999999998
                          children [
                            DEF l_knee_shin Group {
                              children [
                                Transform {
                                  children [
                                    Shape {
                                      appearance Appearance {
                                        material Material {
                                        }
                                      }
                                      geometry Cylinder {
                                        height 0.05
                                        radius 0.019999999999999997
                                        subdivision 10
                                      }
                                    }
                                  ]
                                }
                                Transform {
                                  translation 0.24 0 0
                                  rotation 0 0 1 1.5707996938995747
                                  children [
                                    Shape {
                                      appearance Appearance {
                                        material Material {
                                        }
                                      }
                                      geometry Cylinder {
                                        height 0.48
                                        radius 0.02
                                        subdivision 10
                                      }
                                    }
                                  ]
                                }
                              ]
                            }
                            TouchSensor {
                              translation 0.48 0 0
                              rotation 0 0 1 1.5708003061004252
                              children [
                                DEF r_foot Shape {
                                  appearance Appearance {
                                    material Material {
                                    }
                                  }
                                  geometry Sphere {
                                    radius 0.020000000000000004
                                    subdivision 3
                                  }
                                }
                              ]
                              name "L_foot"
                              boundingObject USE r_foot
                              physics Physics {
                                density -1
                                mass 0.1
                                centerOfMass [
                                  0 0 0
                                ]
                              }
                              type "force-3d"
                              lookupTable [
                                -1000 -1000 0
                                5000 5000 0
                              ]
                            }
                          ]
                          boundingObject USE l_knee_shin
                          physics Physics {
                            density -1
                            mass 1
                            centerOfMass [
                              0.24 0 0
                            ]
                          }
                        }
                      }
                    ]
                    boundingObject USE l_pitch_thigh
                    physics Physics {
                      density -1
                      mass 19.15
                      centerOfMass [
                        0 0 0
                      ]
                    }
                  }
                }
              ]
              name "solid(1)"
              boundingObject USE r_roll_link
              physics Physics {
                density -1
                mass 0.5
                centerOfMass [
                  0 0 0
                ]
              }
            }
          }
          InertialUnit {
            name "IMU"
          }
        ]
        name "solid(2)"
        boundingObject USE body
        physics Physics {
          density -1
          mass 22.2
          centerOfMass [
            0 0 0
          ]
        }
      }
    }
  ]
  controller "3D_controller"
}
